2022-02-16 19:17:37,609 -  nornir.core -     INFO -        run() - Running task 'netmiko_send_command' with args {'command_string': 'sh ip arp '} on 2 hosts
2022-02-16 19:18:24,344 -  nornir.core -     INFO -        run() - Running task 'netmiko_send_command' with args {'command_string': 'dis arp'} on 2 hosts
2022-02-16 19:47:08,228 -  nornir.core -     INFO -        run() - Running task 'netmiko_send_command' with args {'command_string': 'dis arp'} on 1 hosts
2022-02-16 19:52:48,890 -  nornir.core -     INFO -        run() - Running task 'netmiko_send_command' with args {'command_string': 'dis arp | inc 11.14'} on 3 hosts
2022-02-16 20:05:57,441 -  nornir.core -     INFO -        run() - Running task 'config' with args {} on 4 hosts
2022-02-16 20:08:10,764 -  nornir.core -     INFO -        run() - Running task 'config' with args {} on 4 hosts
2022-05-27 18:28:46,479 -  nornir.core -     INFO -        run() - Running task 'config' with args {} on 4 hosts
2022-05-27 18:28:51,503 - nornir.core.task -    ERROR -      start() - Host 'sw2': task 'netmiko_send_config' failed with traceback:
Traceback (most recent call last):
  File "C:\Users\MAKE\AppData\Roaming\Python\Python39\site-packages\netmiko\base_connection.py", line 935, in establish_connection
    self.remote_conn_pre.connect(**ssh_connect_params)
  File "C:\Users\MAKE\AppData\Roaming\Python\Python39\site-packages\paramiko\client.py", line 349, in connect
    retry_on_signal(lambda: sock.connect(addr))
  File "C:\Users\MAKE\AppData\Roaming\Python\Python39\site-packages\paramiko\util.py", line 283, in retry_on_signal
    return function()
  File "C:\Users\MAKE\AppData\Roaming\Python\Python39\site-packages\paramiko\client.py", line 349, in <lambda>
    retry_on_signal(lambda: sock.connect(addr))
socket.timeout: timed out

During handling of the above exception, another exception occurred:

Traceback (most recent call last):
  File "C:\Users\MAKE\AppData\Roaming\Python\Python39\site-packages\nornir\core\task.py", line 99, in start
    r = self.task(self, **self.params)
  File "C:\Users\MAKE\AppData\Roaming\Python\Python39\site-packages\nornir_netmiko\tasks\netmiko_send_config.py", line 28, in netmiko_send_config
    net_connect = task.host.get_connection(CONNECTION_NAME, task.nornir.config)
  File "C:\Users\MAKE\AppData\Roaming\Python\Python39\site-packages\nornir\core\inventory.py", line 494, in get_connection
    self.open_connection(
  File "C:\Users\MAKE\AppData\Roaming\Python\Python39\site-packages\nornir\core\inventory.py", line 546, in open_connection
    conn_obj.open(
  File "C:\Users\MAKE\AppData\Roaming\Python\Python39\site-packages\nornir_netmiko\connections\netmiko.py", line 59, in open
    connection = ConnectHandler(**parameters)
  File "C:\Users\MAKE\AppData\Roaming\Python\Python39\site-packages\netmiko\ssh_dispatcher.py", line 326, in ConnectHandler
    return ConnectionClass(*args, **kwargs)
  File "C:\Users\MAKE\AppData\Roaming\Python\Python39\site-packages\netmiko\base_connection.py", line 350, in __init__
    self._open()
  File "C:\Users\MAKE\AppData\Roaming\Python\Python39\site-packages\netmiko\base_connection.py", line 355, in _open
    self.establish_connection()
  File "C:\Users\MAKE\AppData\Roaming\Python\Python39\site-packages\netmiko\base_connection.py", line 957, in establish_connection
    raise NetmikoTimeoutException(msg)
netmiko.ssh_exception.NetmikoTimeoutException: TCP connection to device failed.

Common causes of this problem are:
1. Incorrect hostname or IP address.
2. Wrong TCP port.
3. Intermediate firewall blocking access.

Device settings: huawei 192.168.11.12:22



2022-05-27 18:28:51,503 - nornir.core.task -    ERROR -      start() - Host 'sw1': task 'netmiko_send_config' failed with traceback:
Traceback (most recent call last):
  File "C:\Users\MAKE\AppData\Roaming\Python\Python39\site-packages\netmiko\base_connection.py", line 935, in establish_connection
    self.remote_conn_pre.connect(**ssh_connect_params)
  File "C:\Users\MAKE\AppData\Roaming\Python\Python39\site-packages\paramiko\client.py", line 349, in connect
    retry_on_signal(lambda: sock.connect(addr))
  File "C:\Users\MAKE\AppData\Roaming\Python\Python39\site-packages\paramiko\util.py", line 283, in retry_on_signal
    return function()
  File "C:\Users\MAKE\AppData\Roaming\Python\Python39\site-packages\paramiko\client.py", line 349, in <lambda>
    retry_on_signal(lambda: sock.connect(addr))
socket.timeout: timed out

During handling of the above exception, another exception occurred:

Traceback (most recent call last):
  File "C:\Users\MAKE\AppData\Roaming\Python\Python39\site-packages\nornir\core\task.py", line 99, in start
    r = self.task(self, **self.params)
  File "C:\Users\MAKE\AppData\Roaming\Python\Python39\site-packages\nornir_netmiko\tasks\netmiko_send_config.py", line 28, in netmiko_send_config
    net_connect = task.host.get_connection(CONNECTION_NAME, task.nornir.config)
  File "C:\Users\MAKE\AppData\Roaming\Python\Python39\site-packages\nornir\core\inventory.py", line 494, in get_connection
    self.open_connection(
  File "C:\Users\MAKE\AppData\Roaming\Python\Python39\site-packages\nornir\core\inventory.py", line 546, in open_connection
    conn_obj.open(
  File "C:\Users\MAKE\AppData\Roaming\Python\Python39\site-packages\nornir_netmiko\connections\netmiko.py", line 59, in open
    connection = ConnectHandler(**parameters)
  File "C:\Users\MAKE\AppData\Roaming\Python\Python39\site-packages\netmiko\ssh_dispatcher.py", line 326, in ConnectHandler
    return ConnectionClass(*args, **kwargs)
  File "C:\Users\MAKE\AppData\Roaming\Python\Python39\site-packages\netmiko\base_connection.py", line 350, in __init__
    self._open()
  File "C:\Users\MAKE\AppData\Roaming\Python\Python39\site-packages\netmiko\base_connection.py", line 355, in _open
    self.establish_connection()
  File "C:\Users\MAKE\AppData\Roaming\Python\Python39\site-packages\netmiko\base_connection.py", line 957, in establish_connection
    raise NetmikoTimeoutException(msg)
netmiko.ssh_exception.NetmikoTimeoutException: TCP connection to device failed.

Common causes of this problem are:
1. Incorrect hostname or IP address.
2. Wrong TCP port.
3. Intermediate firewall blocking access.

Device settings: huawei 192.168.11.11:22



2022-05-27 18:28:51,503 - nornir.core.task -    ERROR -      start() - Host 'sw4': task 'netmiko_send_config' failed with traceback:
Traceback (most recent call last):
  File "C:\Users\MAKE\AppData\Roaming\Python\Python39\site-packages\netmiko\base_connection.py", line 935, in establish_connection
    self.remote_conn_pre.connect(**ssh_connect_params)
  File "C:\Users\MAKE\AppData\Roaming\Python\Python39\site-packages\paramiko\client.py", line 349, in connect
    retry_on_signal(lambda: sock.connect(addr))
  File "C:\Users\MAKE\AppData\Roaming\Python\Python39\site-packages\paramiko\util.py", line 283, in retry_on_signal
    return function()
  File "C:\Users\MAKE\AppData\Roaming\Python\Python39\site-packages\paramiko\client.py", line 349, in <lambda>
    retry_on_signal(lambda: sock.connect(addr))
socket.timeout: timed out

During handling of the above exception, another exception occurred:

Traceback (most recent call last):
  File "C:\Users\MAKE\AppData\Roaming\Python\Python39\site-packages\nornir\core\task.py", line 99, in start
    r = self.task(self, **self.params)
  File "C:\Users\MAKE\AppData\Roaming\Python\Python39\site-packages\nornir_netmiko\tasks\netmiko_send_config.py", line 28, in netmiko_send_config
    net_connect = task.host.get_connection(CONNECTION_NAME, task.nornir.config)
  File "C:\Users\MAKE\AppData\Roaming\Python\Python39\site-packages\nornir\core\inventory.py", line 494, in get_connection
    self.open_connection(
  File "C:\Users\MAKE\AppData\Roaming\Python\Python39\site-packages\nornir\core\inventory.py", line 546, in open_connection
    conn_obj.open(
  File "C:\Users\MAKE\AppData\Roaming\Python\Python39\site-packages\nornir_netmiko\connections\netmiko.py", line 59, in open
    connection = ConnectHandler(**parameters)
  File "C:\Users\MAKE\AppData\Roaming\Python\Python39\site-packages\netmiko\ssh_dispatcher.py", line 326, in ConnectHandler
    return ConnectionClass(*args, **kwargs)
  File "C:\Users\MAKE\AppData\Roaming\Python\Python39\site-packages\netmiko\base_connection.py", line 350, in __init__
    self._open()
  File "C:\Users\MAKE\AppData\Roaming\Python\Python39\site-packages\netmiko\base_connection.py", line 355, in _open
    self.establish_connection()
  File "C:\Users\MAKE\AppData\Roaming\Python\Python39\site-packages\netmiko\base_connection.py", line 957, in establish_connection
    raise NetmikoTimeoutException(msg)
netmiko.ssh_exception.NetmikoTimeoutException: TCP connection to device failed.

Common causes of this problem are:
1. Incorrect hostname or IP address.
2. Wrong TCP port.
3. Intermediate firewall blocking access.

Device settings: huawei 192.168.11.14:22



2022-05-27 18:28:51,503 - nornir.core.task -    ERROR -      start() - Host 'sw3': task 'netmiko_send_config' failed with traceback:
Traceback (most recent call last):
  File "C:\Users\MAKE\AppData\Roaming\Python\Python39\site-packages\netmiko\base_connection.py", line 935, in establish_connection
    self.remote_conn_pre.connect(**ssh_connect_params)
  File "C:\Users\MAKE\AppData\Roaming\Python\Python39\site-packages\paramiko\client.py", line 349, in connect
    retry_on_signal(lambda: sock.connect(addr))
  File "C:\Users\MAKE\AppData\Roaming\Python\Python39\site-packages\paramiko\util.py", line 283, in retry_on_signal
    return function()
  File "C:\Users\MAKE\AppData\Roaming\Python\Python39\site-packages\paramiko\client.py", line 349, in <lambda>
    retry_on_signal(lambda: sock.connect(addr))
socket.timeout: timed out

During handling of the above exception, another exception occurred:

Traceback (most recent call last):
  File "C:\Users\MAKE\AppData\Roaming\Python\Python39\site-packages\nornir\core\task.py", line 99, in start
    r = self.task(self, **self.params)
  File "C:\Users\MAKE\AppData\Roaming\Python\Python39\site-packages\nornir_netmiko\tasks\netmiko_send_config.py", line 28, in netmiko_send_config
    net_connect = task.host.get_connection(CONNECTION_NAME, task.nornir.config)
  File "C:\Users\MAKE\AppData\Roaming\Python\Python39\site-packages\nornir\core\inventory.py", line 494, in get_connection
    self.open_connection(
  File "C:\Users\MAKE\AppData\Roaming\Python\Python39\site-packages\nornir\core\inventory.py", line 546, in open_connection
    conn_obj.open(
  File "C:\Users\MAKE\AppData\Roaming\Python\Python39\site-packages\nornir_netmiko\connections\netmiko.py", line 59, in open
    connection = ConnectHandler(**parameters)
  File "C:\Users\MAKE\AppData\Roaming\Python\Python39\site-packages\netmiko\ssh_dispatcher.py", line 326, in ConnectHandler
    return ConnectionClass(*args, **kwargs)
  File "C:\Users\MAKE\AppData\Roaming\Python\Python39\site-packages\netmiko\base_connection.py", line 350, in __init__
    self._open()
  File "C:\Users\MAKE\AppData\Roaming\Python\Python39\site-packages\netmiko\base_connection.py", line 355, in _open
    self.establish_connection()
  File "C:\Users\MAKE\AppData\Roaming\Python\Python39\site-packages\netmiko\base_connection.py", line 957, in establish_connection
    raise NetmikoTimeoutException(msg)
netmiko.ssh_exception.NetmikoTimeoutException: TCP connection to device failed.

Common causes of this problem are:
1. Incorrect hostname or IP address.
2. Wrong TCP port.
3. Intermediate firewall blocking access.

Device settings: huawei 192.168.11.13:22



2022-05-27 18:28:51,504 - nornir.core.task -    ERROR -      start() - Host 'sw2': task 'config' failed with traceback:
Traceback (most recent call last):
  File "C:\Users\MAKE\AppData\Roaming\Python\Python39\site-packages\nornir\core\task.py", line 99, in start
    r = self.task(self, **self.params)
  File "F:\network_lab\nornir\lab6\6_lab.py", line 9, in config
    huawei.run(task=netmiko_send_config, config_file='commands.cfg')
  File "C:\Users\MAKE\AppData\Roaming\Python\Python39\site-packages\nornir\core\task.py", line 174, in run
    raise NornirSubTaskError(task=run_task, result=r)
nornir.core.exceptions.NornirSubTaskError: Subtask: netmiko_send_config (failed)


2022-05-27 18:28:51,509 - nornir.core.task -    ERROR -      start() - Host 'sw1': task 'config' failed with traceback:
Traceback (most recent call last):
  File "C:\Users\MAKE\AppData\Roaming\Python\Python39\site-packages\nornir\core\task.py", line 99, in start
    r = self.task(self, **self.params)
  File "F:\network_lab\nornir\lab6\6_lab.py", line 9, in config
    huawei.run(task=netmiko_send_config, config_file='commands.cfg')
  File "C:\Users\MAKE\AppData\Roaming\Python\Python39\site-packages\nornir\core\task.py", line 174, in run
    raise NornirSubTaskError(task=run_task, result=r)
nornir.core.exceptions.NornirSubTaskError: Subtask: netmiko_send_config (failed)


2022-05-27 18:28:51,510 - nornir.core.task -    ERROR -      start() - Host 'sw4': task 'config' failed with traceback:
Traceback (most recent call last):
  File "C:\Users\MAKE\AppData\Roaming\Python\Python39\site-packages\nornir\core\task.py", line 99, in start
    r = self.task(self, **self.params)
  File "F:\network_lab\nornir\lab6\6_lab.py", line 9, in config
    huawei.run(task=netmiko_send_config, config_file='commands.cfg')
  File "C:\Users\MAKE\AppData\Roaming\Python\Python39\site-packages\nornir\core\task.py", line 174, in run
    raise NornirSubTaskError(task=run_task, result=r)
nornir.core.exceptions.NornirSubTaskError: Subtask: netmiko_send_config (failed)


2022-05-27 18:28:51,510 - nornir.core.task -    ERROR -      start() - Host 'sw3': task 'config' failed with traceback:
Traceback (most recent call last):
  File "C:\Users\MAKE\AppData\Roaming\Python\Python39\site-packages\nornir\core\task.py", line 99, in start
    r = self.task(self, **self.params)
  File "F:\network_lab\nornir\lab6\6_lab.py", line 9, in config
    huawei.run(task=netmiko_send_config, config_file='commands.cfg')
  File "C:\Users\MAKE\AppData\Roaming\Python\Python39\site-packages\nornir\core\task.py", line 174, in run
    raise NornirSubTaskError(task=run_task, result=r)
nornir.core.exceptions.NornirSubTaskError: Subtask: netmiko_send_config (failed)


2022-06-29 16:36:43,658 -  nornir.core -     INFO -        run() - Running task 'config' with args {} on 4 hosts
2022-06-29 16:41:00,016 -  nornir.core -     INFO -        run() - Running task 'config' with args {} on 4 hosts
